[2025-10-15T17:42:01.873+0000] {local_task_job_runner.py:120} INFO - ::group::Pre task execution logs
[2025-10-15T17:42:01.888+0000] {taskinstance.py:2076} INFO - Dependencies all met for dep_context=non-requeueable deps ti=<TaskInstance: game_sentiment_data_pipeline.silver_dbt_gm_rvws_smry manual__2025-10-15T17:40:55.992125+00:00 [queued]>
[2025-10-15T17:42:01.893+0000] {taskinstance.py:2076} INFO - Dependencies all met for dep_context=requeueable deps ti=<TaskInstance: game_sentiment_data_pipeline.silver_dbt_gm_rvws_smry manual__2025-10-15T17:40:55.992125+00:00 [queued]>
[2025-10-15T17:42:01.893+0000] {taskinstance.py:2306} INFO - Starting attempt 1 of 1
[2025-10-15T17:42:01.900+0000] {taskinstance.py:2330} INFO - Executing <Task(PythonOperator): silver_dbt_gm_rvws_smry> on 2025-10-15 17:40:55.992125+00:00
[2025-10-15T17:42:01.903+0000] {warnings.py:112} WARNING - /home/***/.local/lib/python3.12/site-packages/***/task/task_runner/standard_task_runner.py:62: DeprecationWarning: This process (pid=193) is multi-threaded, use of fork() may lead to deadlocks in the child.
  pid = os.fork()

[2025-10-15T17:42:01.904+0000] {standard_task_runner.py:64} INFO - Started process 194 to run task
[2025-10-15T17:42:01.905+0000] {standard_task_runner.py:90} INFO - Running: ['***', 'tasks', 'run', 'game_sentiment_data_pipeline', 'silver_dbt_gm_rvws_smry', 'manual__2025-10-15T17:40:55.992125+00:00', '--job-id', '16', '--raw', '--subdir', 'DAGS_FOLDER/dag_pipeline.py', '--cfg-path', '/tmp/tmpilbs16bl']
[2025-10-15T17:42:01.906+0000] {standard_task_runner.py:91} INFO - Job 16: Subtask silver_dbt_gm_rvws_smry
[2025-10-15T17:42:01.931+0000] {task_command.py:426} INFO - Running <TaskInstance: game_sentiment_data_pipeline.silver_dbt_gm_rvws_smry manual__2025-10-15T17:40:55.992125+00:00 [running]> on host 1a3259f82575
[2025-10-15T17:42:01.974+0000] {taskinstance.py:2648} INFO - Exporting env vars: AIRFLOW_CTX_DAG_OWNER='***' AIRFLOW_CTX_DAG_ID='game_sentiment_data_pipeline' AIRFLOW_CTX_TASK_ID='silver_dbt_gm_rvws_smry' AIRFLOW_CTX_EXECUTION_DATE='2025-10-15T17:40:55.992125+00:00' AIRFLOW_CTX_TRY_NUMBER='1' AIRFLOW_CTX_DAG_RUN_ID='manual__2025-10-15T17:40:55.992125+00:00'
[2025-10-15T17:42:01.975+0000] {taskinstance.py:430} INFO - ::endgroup::
[2025-10-15T17:42:01.984+0000] {taskinstance.py:441} INFO - ::group::Post task execution logs
[2025-10-15T17:42:01.984+0000] {taskinstance.py:2905} ERROR - Task failed with exception
Traceback (most recent call last):
  File "/home/airflow/.local/lib/python3.12/site-packages/airflow/models/taskinstance.py", line 465, in _execute_task
    result = _execute_callable(context=context, **execute_callable_kwargs)
             ^^^^^^^^^^^^^^^^^^^^^^^^^^^^^^^^^^^^^^^^^^^^^^^^^^^^^^^^^^^^^
  File "/home/airflow/.local/lib/python3.12/site-packages/airflow/models/taskinstance.py", line 432, in _execute_callable
    return execute_callable(context=context, **execute_callable_kwargs)
           ^^^^^^^^^^^^^^^^^^^^^^^^^^^^^^^^^^^^^^^^^^^^^^^^^^^^^^^^^^^^
  File "/home/airflow/.local/lib/python3.12/site-packages/airflow/models/baseoperator.py", line 401, in wrapper
    return func(self, *args, **kwargs)
           ^^^^^^^^^^^^^^^^^^^^^^^^^^^
  File "/home/airflow/.local/lib/python3.12/site-packages/airflow/operators/python.py", line 235, in execute
    return_value = self.execute_callable()
                   ^^^^^^^^^^^^^^^^^^^^^^^
  File "/home/airflow/.local/lib/python3.12/site-packages/airflow/operators/python.py", line 252, in execute_callable
    return self.python_callable(*self.op_args, **self.op_kwargs)
           ^^^^^^^^^^^^^^^^^^^^^^^^^^^^^^^^^^^^^^^^^^^^^^^^^^^^^
  File "/opt/airflow/dags/dag_pipeline.py", line 33, in run_dbt
    subprocess.run(["dbt","run","--select",f"{model_name}"],cwd="/Users/ameedahmed/Desktop/my_lambda_docker/docker_folder_files/airflow/silver_layer",check=True)
  File "/usr/local/lib/python3.12/subprocess.py", line 548, in run
    with Popen(*popenargs, **kwargs) as process:
         ^^^^^^^^^^^^^^^^^^^^^^^^^^^
  File "/usr/local/lib/python3.12/subprocess.py", line 1026, in __init__
    self._execute_child(args, executable, preexec_fn, close_fds,
  File "/usr/local/lib/python3.12/subprocess.py", line 1955, in _execute_child
    raise child_exception_type(errno_num, err_msg, err_filename)
FileNotFoundError: [Errno 2] No such file or directory: '/Users/ameedahmed/Desktop/my_lambda_docker/docker_folder_files/airflow/silver_layer'
[2025-10-15T17:42:01.990+0000] {taskinstance.py:1206} INFO - Marking task as FAILED. dag_id=game_sentiment_data_pipeline, task_id=silver_dbt_gm_rvws_smry, run_id=manual__2025-10-15T17:40:55.992125+00:00, execution_date=20251015T174055, start_date=20251015T174201, end_date=20251015T174201
[2025-10-15T17:42:01.996+0000] {standard_task_runner.py:110} ERROR - Failed to execute job 16 for task silver_dbt_gm_rvws_smry ([Errno 2] No such file or directory: '/Users/ameedahmed/Desktop/my_lambda_docker/docker_folder_files/airflow/silver_layer'; 194)
[2025-10-15T17:42:02.005+0000] {local_task_job_runner.py:243} INFO - Task exited with return code 1
[2025-10-15T17:42:02.018+0000] {taskinstance.py:3503} INFO - 0 downstream tasks scheduled from follow-on schedule check
[2025-10-15T17:42:02.020+0000] {local_task_job_runner.py:222} INFO - ::endgroup::
