[2025-10-15T17:55:45.076+0000] {local_task_job_runner.py:120} INFO - ::group::Pre task execution logs
[2025-10-15T17:55:45.087+0000] {taskinstance.py:2076} INFO - Dependencies all met for dep_context=non-requeueable deps ti=<TaskInstance: game_sentiment_data_pipeline.bronze_lambda_gms_rvws manual__2025-10-15T17:55:44.018345+00:00 [queued]>
[2025-10-15T17:55:45.090+0000] {taskinstance.py:2076} INFO - Dependencies all met for dep_context=requeueable deps ti=<TaskInstance: game_sentiment_data_pipeline.bronze_lambda_gms_rvws manual__2025-10-15T17:55:44.018345+00:00 [queued]>
[2025-10-15T17:55:45.091+0000] {taskinstance.py:2306} INFO - Starting attempt 1 of 1
[2025-10-15T17:55:45.095+0000] {taskinstance.py:2330} INFO - Executing <Task(PythonOperator): bronze_lambda_gms_rvws> on 2025-10-15 17:55:44.018345+00:00
[2025-10-15T17:55:45.097+0000] {warnings.py:112} WARNING - /home/***/.local/lib/python3.12/site-packages/***/task/task_runner/standard_task_runner.py:62: DeprecationWarning: This process (pid=163) is multi-threaded, use of fork() may lead to deadlocks in the child.
  pid = os.fork()

[2025-10-15T17:55:45.098+0000] {standard_task_runner.py:64} INFO - Started process 164 to run task
[2025-10-15T17:55:45.098+0000] {standard_task_runner.py:90} INFO - Running: ['***', 'tasks', 'run', 'game_sentiment_data_pipeline', 'bronze_lambda_gms_rvws', 'manual__2025-10-15T17:55:44.018345+00:00', '--job-id', '26', '--raw', '--subdir', 'DAGS_FOLDER/dag_pipeline.py', '--cfg-path', '/tmp/tmp5e_97w_p']
[2025-10-15T17:55:45.099+0000] {standard_task_runner.py:91} INFO - Job 26: Subtask bronze_lambda_gms_rvws
[2025-10-15T17:55:45.116+0000] {task_command.py:426} INFO - Running <TaskInstance: game_sentiment_data_pipeline.bronze_lambda_gms_rvws manual__2025-10-15T17:55:44.018345+00:00 [running]> on host e6988e140737
[2025-10-15T17:55:45.145+0000] {taskinstance.py:2648} INFO - Exporting env vars: AIRFLOW_CTX_DAG_OWNER='***' AIRFLOW_CTX_DAG_ID='game_sentiment_data_pipeline' AIRFLOW_CTX_TASK_ID='bronze_lambda_gms_rvws' AIRFLOW_CTX_EXECUTION_DATE='2025-10-15T17:55:44.018345+00:00' AIRFLOW_CTX_TRY_NUMBER='1' AIRFLOW_CTX_DAG_RUN_ID='manual__2025-10-15T17:55:44.018345+00:00'
[2025-10-15T17:55:45.145+0000] {taskinstance.py:430} INFO - ::endgroup::
[2025-10-15T17:55:45.151+0000] {logging_mixin.py:188} INFO - Invoking Lambda function: bronze_lambda_with_docker
[2025-10-15T17:56:00.246+0000] {local_task_job_runner.py:313} WARNING - State of this instance has been externally set to None. Terminating instance.
[2025-10-15T17:56:00.248+0000] {local_task_job_runner.py:222} INFO - ::endgroup::
[2025-10-15T17:56:00.249+0000] {process_utils.py:132} INFO - Sending 15 to group 164. PIDs of all processes in the group: [164]
[2025-10-15T17:56:00.250+0000] {process_utils.py:87} INFO - Sending the signal 15 to group 164
[2025-10-15T17:56:00.250+0000] {taskinstance.py:2611} ERROR - Received SIGTERM. Terminating subprocesses.
[2025-10-15T17:56:00.251+0000] {taskinstance.py:441} INFO - ::group::Post task execution logs
[2025-10-15T17:56:00.256+0000] {taskinstance.py:2905} ERROR - Task failed with exception
Traceback (most recent call last):
  File "/home/airflow/.local/lib/python3.12/site-packages/airflow/models/taskinstance.py", line 465, in _execute_task
    result = _execute_callable(context=context, **execute_callable_kwargs)
             ^^^^^^^^^^^^^^^^^^^^^^^^^^^^^^^^^^^^^^^^^^^^^^^^^^^^^^^^^^^^^
  File "/home/airflow/.local/lib/python3.12/site-packages/airflow/models/taskinstance.py", line 432, in _execute_callable
    return execute_callable(context=context, **execute_callable_kwargs)
           ^^^^^^^^^^^^^^^^^^^^^^^^^^^^^^^^^^^^^^^^^^^^^^^^^^^^^^^^^^^^
  File "/home/airflow/.local/lib/python3.12/site-packages/airflow/models/baseoperator.py", line 401, in wrapper
    return func(self, *args, **kwargs)
           ^^^^^^^^^^^^^^^^^^^^^^^^^^^
  File "/home/airflow/.local/lib/python3.12/site-packages/airflow/operators/python.py", line 235, in execute
    return_value = self.execute_callable()
                   ^^^^^^^^^^^^^^^^^^^^^^^
  File "/home/airflow/.local/lib/python3.12/site-packages/airflow/operators/python.py", line 252, in execute_callable
    return self.python_callable(*self.op_args, **self.op_kwargs)
           ^^^^^^^^^^^^^^^^^^^^^^^^^^^^^^^^^^^^^^^^^^^^^^^^^^^^^
  File "/opt/airflow/dags/dag_pipeline.py", line 22, in run_lambda
    response = lambda_client.invoke(
               ^^^^^^^^^^^^^^^^^^^^^
  File "/home/airflow/.local/lib/python3.12/site-packages/botocore/client.py", line 565, in _api_call
    return self._make_api_call(operation_name, kwargs)
           ^^^^^^^^^^^^^^^^^^^^^^^^^^^^^^^^^^^^^^^^^^^
  File "/home/airflow/.local/lib/python3.12/site-packages/botocore/client.py", line 1001, in _make_api_call
    http, parsed_response = self._make_request(
                            ^^^^^^^^^^^^^^^^^^^
  File "/home/airflow/.local/lib/python3.12/site-packages/botocore/client.py", line 1027, in _make_request
    return self._endpoint.make_request(operation_model, request_dict)
           ^^^^^^^^^^^^^^^^^^^^^^^^^^^^^^^^^^^^^^^^^^^^^^^^^^^^^^^^^^
  File "/home/airflow/.local/lib/python3.12/site-packages/botocore/endpoint.py", line 119, in make_request
    return self._send_request(request_dict, operation_model)
           ^^^^^^^^^^^^^^^^^^^^^^^^^^^^^^^^^^^^^^^^^^^^^^^^^
  File "/home/airflow/.local/lib/python3.12/site-packages/botocore/endpoint.py", line 199, in _send_request
    success_response, exception = self._get_response(
                                  ^^^^^^^^^^^^^^^^^^^
  File "/home/airflow/.local/lib/python3.12/site-packages/botocore/endpoint.py", line 241, in _get_response
    success_response, exception = self._do_get_response(
                                  ^^^^^^^^^^^^^^^^^^^^^^
  File "/home/airflow/.local/lib/python3.12/site-packages/botocore/endpoint.py", line 281, in _do_get_response
    http_response = self._send(request)
                    ^^^^^^^^^^^^^^^^^^^
  File "/home/airflow/.local/lib/python3.12/site-packages/botocore/endpoint.py", line 377, in _send
    return self.http_session.send(request)
           ^^^^^^^^^^^^^^^^^^^^^^^^^^^^^^^
  File "/home/airflow/.local/lib/python3.12/site-packages/botocore/httpsession.py", line 464, in send
    urllib_response = conn.urlopen(
                      ^^^^^^^^^^^^^
  File "/home/airflow/.local/lib/python3.12/site-packages/urllib3/connectionpool.py", line 791, in urlopen
    response = self._make_request(
               ^^^^^^^^^^^^^^^^^^^
  File "/home/airflow/.local/lib/python3.12/site-packages/urllib3/connectionpool.py", line 537, in _make_request
    response = conn.getresponse()
               ^^^^^^^^^^^^^^^^^^
  File "/home/airflow/.local/lib/python3.12/site-packages/urllib3/connection.py", line 461, in getresponse
    httplib_response = super().getresponse()
                       ^^^^^^^^^^^^^^^^^^^^^
  File "/usr/local/lib/python3.12/http/client.py", line 1428, in getresponse
    response.begin()
  File "/usr/local/lib/python3.12/http/client.py", line 331, in begin
    version, status, reason = self._read_status()
                              ^^^^^^^^^^^^^^^^^^^
  File "/usr/local/lib/python3.12/http/client.py", line 292, in _read_status
    line = str(self.fp.readline(_MAXLINE + 1), "iso-8859-1")
               ^^^^^^^^^^^^^^^^^^^^^^^^^^^^^^
  File "/usr/local/lib/python3.12/socket.py", line 708, in readinto
    return self._sock.recv_into(b)
           ^^^^^^^^^^^^^^^^^^^^^^^
  File "/usr/local/lib/python3.12/ssl.py", line 1252, in recv_into
    return self.read(nbytes, buffer)
           ^^^^^^^^^^^^^^^^^^^^^^^^^
  File "/usr/local/lib/python3.12/ssl.py", line 1104, in read
    return self._sslobj.read(len, buffer)
           ^^^^^^^^^^^^^^^^^^^^^^^^^^^^^^
  File "/home/airflow/.local/lib/python3.12/site-packages/airflow/models/taskinstance.py", line 2613, in signal_handler
    raise AirflowTaskTerminated("Task received SIGTERM signal")
airflow.exceptions.AirflowTaskTerminated: Task received SIGTERM signal
[2025-10-15T17:56:00.260+0000] {taskinstance.py:1206} INFO - Marking task as FAILED. dag_id=game_sentiment_data_pipeline, task_id=bronze_lambda_gms_rvws, run_id=manual__2025-10-15T17:55:44.018345+00:00, execution_date=20251015T175544, start_date=20251015T175545, end_date=20251015T175600
[2025-10-15T17:56:00.266+0000] {standard_task_runner.py:110} ERROR - Failed to execute job 26 for task bronze_lambda_gms_rvws ((psycopg2.errors.ForeignKeyViolation) insert or update on table "task_fail" violates foreign key constraint "task_fail_ti_fkey"
DETAIL:  Key (dag_id, task_id, run_id, map_index)=(game_sentiment_data_pipeline, bronze_lambda_gms_rvws, manual__2025-10-15T17:55:44.018345+00:00, -1) is not present in table "task_instance".

[SQL: INSERT INTO task_fail (task_id, dag_id, run_id, map_index, start_date, end_date, duration) VALUES (%(task_id)s, %(dag_id)s, %(run_id)s, %(map_index)s, %(start_date)s, %(end_date)s, %(duration)s) RETURNING task_fail.id]
[parameters: {'task_id': 'bronze_lambda_gms_rvws', 'dag_id': 'game_sentiment_data_pipeline', 'run_id': 'manual__2025-10-15T17:55:44.018345+00:00', 'map_index': -1, 'start_date': datetime.datetime(2025, 10, 15, 17, 55, 45, 87873, tzinfo=Timezone('UTC')), 'end_date': datetime.datetime(2025, 10, 15, 17, 56, 0, 260114, tzinfo=Timezone('UTC')), 'duration': 15}]
(Background on this error at: https://sqlalche.me/e/14/gkpj); 164)
[2025-10-15T17:56:00.281+0000] {process_utils.py:80} INFO - Process psutil.Process(pid=164, status='terminated', exitcode=1, started='17:55:44') (164) terminated with exit code 1
