[2025-10-15T18:56:54.444+0000] {local_task_job_runner.py:120} INFO - ::group::Pre task execution logs
[2025-10-15T18:56:54.459+0000] {taskinstance.py:2076} INFO - Dependencies all met for dep_context=non-requeueable deps ti=<TaskInstance: game_sentiment_data_pipeline.dbt_run manual__2025-10-15T18:56:04.740938+00:00 [queued]>
[2025-10-15T18:56:54.465+0000] {taskinstance.py:2076} INFO - Dependencies all met for dep_context=requeueable deps ti=<TaskInstance: game_sentiment_data_pipeline.dbt_run manual__2025-10-15T18:56:04.740938+00:00 [queued]>
[2025-10-15T18:56:54.465+0000] {taskinstance.py:2306} INFO - Starting attempt 1 of 1
[2025-10-15T18:56:54.471+0000] {taskinstance.py:2330} INFO - Executing <Task(BashOperator): dbt_run> on 2025-10-15 18:56:04.740938+00:00
[2025-10-15T18:56:54.476+0000] {warnings.py:112} WARNING - /home/***/.local/lib/python3.12/site-packages/***/task/task_runner/standard_task_runner.py:62: DeprecationWarning: This process (pid=167) is multi-threaded, use of fork() may lead to deadlocks in the child.
  pid = os.fork()

[2025-10-15T18:56:54.476+0000] {standard_task_runner.py:90} INFO - Running: ['***', 'tasks', 'run', 'game_sentiment_data_pipeline', 'dbt_run', 'manual__2025-10-15T18:56:04.740938+00:00', '--job-id', '49', '--raw', '--subdir', 'DAGS_FOLDER/dag_pipeline.py', '--cfg-path', '/tmp/tmpuaa1o7iz']
[2025-10-15T18:56:54.477+0000] {standard_task_runner.py:64} INFO - Started process 168 to run task
[2025-10-15T18:56:54.477+0000] {standard_task_runner.py:91} INFO - Job 49: Subtask dbt_run
[2025-10-15T18:56:54.499+0000] {task_command.py:426} INFO - Running <TaskInstance: game_sentiment_data_pipeline.dbt_run manual__2025-10-15T18:56:04.740938+00:00 [running]> on host 9c9293c52211
[2025-10-15T18:56:54.533+0000] {taskinstance.py:2648} INFO - Exporting env vars: AIRFLOW_CTX_DAG_OWNER='***' AIRFLOW_CTX_DAG_ID='game_sentiment_data_pipeline' AIRFLOW_CTX_TASK_ID='dbt_run' AIRFLOW_CTX_EXECUTION_DATE='2025-10-15T18:56:04.740938+00:00' AIRFLOW_CTX_TRY_NUMBER='1' AIRFLOW_CTX_DAG_RUN_ID='manual__2025-10-15T18:56:04.740938+00:00'
[2025-10-15T18:56:54.533+0000] {taskinstance.py:430} INFO - ::endgroup::
[2025-10-15T18:56:54.539+0000] {subprocess.py:63} INFO - Tmp dir root location: /tmp
[2025-10-15T18:56:54.540+0000] {subprocess.py:75} INFO - Running command: ['/usr/bin/bash', '-c', 'cd /opt/***/silver_layer && dbt run']
[2025-10-15T18:56:54.545+0000] {subprocess.py:86} INFO - Output:
[2025-10-15T18:56:54.546+0000] {subprocess.py:93} INFO - /usr/bin/bash: line 1: dbt: command not found
[2025-10-15T18:56:54.546+0000] {subprocess.py:97} INFO - Command exited with return code 127
[2025-10-15T18:56:54.546+0000] {taskinstance.py:441} INFO - ::group::Post task execution logs
[2025-10-15T18:56:54.551+0000] {taskinstance.py:2905} ERROR - Task failed with exception
Traceback (most recent call last):
  File "/home/airflow/.local/lib/python3.12/site-packages/airflow/models/taskinstance.py", line 465, in _execute_task
    result = _execute_callable(context=context, **execute_callable_kwargs)
             ^^^^^^^^^^^^^^^^^^^^^^^^^^^^^^^^^^^^^^^^^^^^^^^^^^^^^^^^^^^^^
  File "/home/airflow/.local/lib/python3.12/site-packages/airflow/models/taskinstance.py", line 432, in _execute_callable
    return execute_callable(context=context, **execute_callable_kwargs)
           ^^^^^^^^^^^^^^^^^^^^^^^^^^^^^^^^^^^^^^^^^^^^^^^^^^^^^^^^^^^^
  File "/home/airflow/.local/lib/python3.12/site-packages/airflow/models/baseoperator.py", line 401, in wrapper
    return func(self, *args, **kwargs)
           ^^^^^^^^^^^^^^^^^^^^^^^^^^^
  File "/home/airflow/.local/lib/python3.12/site-packages/airflow/operators/bash.py", line 243, in execute
    raise AirflowException(
airflow.exceptions.AirflowException: Bash command failed. The command returned a non-zero exit code 127.
[2025-10-15T18:56:54.553+0000] {taskinstance.py:1206} INFO - Marking task as FAILED. dag_id=game_sentiment_data_pipeline, task_id=dbt_run, run_id=manual__2025-10-15T18:56:04.740938+00:00, execution_date=20251015T185604, start_date=20251015T185654, end_date=20251015T185654
[2025-10-15T18:56:54.558+0000] {standard_task_runner.py:110} ERROR - Failed to execute job 49 for task dbt_run (Bash command failed. The command returned a non-zero exit code 127.; 168)
[2025-10-15T18:56:54.578+0000] {local_task_job_runner.py:243} INFO - Task exited with return code 1
[2025-10-15T18:56:54.587+0000] {taskinstance.py:3503} INFO - 0 downstream tasks scheduled from follow-on schedule check
[2025-10-15T18:56:54.589+0000] {local_task_job_runner.py:222} INFO - ::endgroup::
