[2025-10-21T22:56:34.696+0000] {local_task_job_runner.py:120} INFO - ::group::Pre task execution logs
[2025-10-21T22:56:34.708+0000] {taskinstance.py:2076} INFO - Dependencies all met for dep_context=non-requeueable deps ti=<TaskInstance: game_sentiment_data_pipeline.sent_analysis manual__2025-10-21T22:55:02.148183+00:00 [queued]>
[2025-10-21T22:56:34.711+0000] {taskinstance.py:2076} INFO - Dependencies all met for dep_context=requeueable deps ti=<TaskInstance: game_sentiment_data_pipeline.sent_analysis manual__2025-10-21T22:55:02.148183+00:00 [queued]>
[2025-10-21T22:56:34.712+0000] {taskinstance.py:2306} INFO - Starting attempt 1 of 1
[2025-10-21T22:56:34.716+0000] {taskinstance.py:2330} INFO - Executing <Task(PythonOperator): sent_analysis> on 2025-10-21 22:55:02.148183+00:00
[2025-10-21T22:56:34.719+0000] {warnings.py:112} WARNING - /home/***/.local/lib/python3.12/site-packages/***/task/task_runner/standard_task_runner.py:62: DeprecationWarning: This process (pid=162) is multi-threaded, use of fork() may lead to deadlocks in the child.
  pid = os.fork()

[2025-10-21T22:56:34.719+0000] {standard_task_runner.py:64} INFO - Started process 163 to run task
[2025-10-21T22:56:34.720+0000] {standard_task_runner.py:90} INFO - Running: ['***', 'tasks', 'run', 'game_sentiment_data_pipeline', 'sent_analysis', 'manual__2025-10-21T22:55:02.148183+00:00', '--job-id', '124', '--raw', '--subdir', 'DAGS_FOLDER/dag_pipeline.py', '--cfg-path', '/tmp/tmpbi0zk4js']
[2025-10-21T22:56:34.720+0000] {standard_task_runner.py:91} INFO - Job 124: Subtask sent_analysis
[2025-10-21T22:56:34.738+0000] {task_command.py:426} INFO - Running <TaskInstance: game_sentiment_data_pipeline.sent_analysis manual__2025-10-21T22:55:02.148183+00:00 [running]> on host 78a5e601f5ac
[2025-10-21T22:56:34.768+0000] {taskinstance.py:2648} INFO - Exporting env vars: AIRFLOW_CTX_DAG_OWNER='***' AIRFLOW_CTX_DAG_ID='game_sentiment_data_pipeline' AIRFLOW_CTX_TASK_ID='sent_analysis' AIRFLOW_CTX_EXECUTION_DATE='2025-10-21T22:55:02.148183+00:00' AIRFLOW_CTX_TRY_NUMBER='1' AIRFLOW_CTX_DAG_RUN_ID='manual__2025-10-21T22:55:02.148183+00:00'
[2025-10-21T22:56:34.769+0000] {taskinstance.py:430} INFO - ::endgroup::
[2025-10-21T22:56:34.774+0000] {logging_mixin.py:188} INFO - Invoking Lambda function: sentiment_ntbk
[2025-10-21T23:01:45.404+0000] {taskinstance.py:441} INFO - ::group::Post task execution logs
[2025-10-21T23:01:45.409+0000] {taskinstance.py:2905} ERROR - Task failed with exception
Traceback (most recent call last):
  File "/home/airflow/.local/lib/python3.12/site-packages/urllib3/connectionpool.py", line 537, in _make_request
    response = conn.getresponse()
               ^^^^^^^^^^^^^^^^^^
  File "/home/airflow/.local/lib/python3.12/site-packages/urllib3/connection.py", line 461, in getresponse
    httplib_response = super().getresponse()
                       ^^^^^^^^^^^^^^^^^^^^^
  File "/usr/local/lib/python3.12/http/client.py", line 1428, in getresponse
    response.begin()
  File "/usr/local/lib/python3.12/http/client.py", line 331, in begin
    version, status, reason = self._read_status()
                              ^^^^^^^^^^^^^^^^^^^
  File "/usr/local/lib/python3.12/http/client.py", line 292, in _read_status
    line = str(self.fp.readline(_MAXLINE + 1), "iso-8859-1")
               ^^^^^^^^^^^^^^^^^^^^^^^^^^^^^^
  File "/usr/local/lib/python3.12/socket.py", line 708, in readinto
    return self._sock.recv_into(b)
           ^^^^^^^^^^^^^^^^^^^^^^^
  File "/usr/local/lib/python3.12/ssl.py", line 1252, in recv_into
    return self.read(nbytes, buffer)
           ^^^^^^^^^^^^^^^^^^^^^^^^^
  File "/usr/local/lib/python3.12/ssl.py", line 1104, in read
    return self._sslobj.read(len, buffer)
           ^^^^^^^^^^^^^^^^^^^^^^^^^^^^^^
TimeoutError: The read operation timed out

The above exception was the direct cause of the following exception:

Traceback (most recent call last):
  File "/home/airflow/.local/lib/python3.12/site-packages/botocore/httpsession.py", line 464, in send
    urllib_response = conn.urlopen(
                      ^^^^^^^^^^^^^
  File "/home/airflow/.local/lib/python3.12/site-packages/urllib3/connectionpool.py", line 845, in urlopen
    retries = retries.increment(
              ^^^^^^^^^^^^^^^^^^
  File "/home/airflow/.local/lib/python3.12/site-packages/urllib3/util/retry.py", line 445, in increment
    raise reraise(type(error), error, _stacktrace)
          ^^^^^^^^^^^^^^^^^^^^^^^^^^^^^^^^^^^^^^^^
  File "/home/airflow/.local/lib/python3.12/site-packages/urllib3/util/util.py", line 39, in reraise
    raise value
  File "/home/airflow/.local/lib/python3.12/site-packages/urllib3/connectionpool.py", line 791, in urlopen
    response = self._make_request(
               ^^^^^^^^^^^^^^^^^^^
  File "/home/airflow/.local/lib/python3.12/site-packages/urllib3/connectionpool.py", line 539, in _make_request
    self._raise_timeout(err=e, url=url, timeout_value=read_timeout)
  File "/home/airflow/.local/lib/python3.12/site-packages/urllib3/connectionpool.py", line 371, in _raise_timeout
    raise ReadTimeoutError(
urllib3.exceptions.ReadTimeoutError: AWSHTTPSConnectionPool(host='lambda.eu-central-1.amazonaws.com', port=443): Read timed out. (read timeout=60)

During handling of the above exception, another exception occurred:

Traceback (most recent call last):
  File "/home/airflow/.local/lib/python3.12/site-packages/airflow/models/taskinstance.py", line 465, in _execute_task
    result = _execute_callable(context=context, **execute_callable_kwargs)
             ^^^^^^^^^^^^^^^^^^^^^^^^^^^^^^^^^^^^^^^^^^^^^^^^^^^^^^^^^^^^^
  File "/home/airflow/.local/lib/python3.12/site-packages/airflow/models/taskinstance.py", line 432, in _execute_callable
    return execute_callable(context=context, **execute_callable_kwargs)
           ^^^^^^^^^^^^^^^^^^^^^^^^^^^^^^^^^^^^^^^^^^^^^^^^^^^^^^^^^^^^
  File "/home/airflow/.local/lib/python3.12/site-packages/airflow/models/baseoperator.py", line 401, in wrapper
    return func(self, *args, **kwargs)
           ^^^^^^^^^^^^^^^^^^^^^^^^^^^
  File "/home/airflow/.local/lib/python3.12/site-packages/airflow/operators/python.py", line 235, in execute
    return_value = self.execute_callable()
                   ^^^^^^^^^^^^^^^^^^^^^^^
  File "/home/airflow/.local/lib/python3.12/site-packages/airflow/operators/python.py", line 252, in execute_callable
    return self.python_callable(*self.op_args, **self.op_kwargs)
           ^^^^^^^^^^^^^^^^^^^^^^^^^^^^^^^^^^^^^^^^^^^^^^^^^^^^^
  File "/opt/airflow/dags/dag_pipeline.py", line 24, in run_lambda
    response = lambda_client.invoke(
               ^^^^^^^^^^^^^^^^^^^^^
  File "/home/airflow/.local/lib/python3.12/site-packages/botocore/client.py", line 565, in _api_call
    return self._make_api_call(operation_name, kwargs)
           ^^^^^^^^^^^^^^^^^^^^^^^^^^^^^^^^^^^^^^^^^^^
  File "/home/airflow/.local/lib/python3.12/site-packages/botocore/client.py", line 1001, in _make_api_call
    http, parsed_response = self._make_request(
                            ^^^^^^^^^^^^^^^^^^^
  File "/home/airflow/.local/lib/python3.12/site-packages/botocore/client.py", line 1027, in _make_request
    return self._endpoint.make_request(operation_model, request_dict)
           ^^^^^^^^^^^^^^^^^^^^^^^^^^^^^^^^^^^^^^^^^^^^^^^^^^^^^^^^^^
  File "/home/airflow/.local/lib/python3.12/site-packages/botocore/endpoint.py", line 119, in make_request
    return self._send_request(request_dict, operation_model)
           ^^^^^^^^^^^^^^^^^^^^^^^^^^^^^^^^^^^^^^^^^^^^^^^^^
  File "/home/airflow/.local/lib/python3.12/site-packages/botocore/endpoint.py", line 202, in _send_request
    while self._needs_retry(
          ^^^^^^^^^^^^^^^^^^
  File "/home/airflow/.local/lib/python3.12/site-packages/botocore/endpoint.py", line 354, in _needs_retry
    responses = self._event_emitter.emit(
                ^^^^^^^^^^^^^^^^^^^^^^^^^
  File "/home/airflow/.local/lib/python3.12/site-packages/botocore/hooks.py", line 412, in emit
    return self._emitter.emit(aliased_event_name, **kwargs)
           ^^^^^^^^^^^^^^^^^^^^^^^^^^^^^^^^^^^^^^^^^^^^^^^^
  File "/home/airflow/.local/lib/python3.12/site-packages/botocore/hooks.py", line 256, in emit
    return self._emit(event_name, kwargs)
           ^^^^^^^^^^^^^^^^^^^^^^^^^^^^^^
  File "/home/airflow/.local/lib/python3.12/site-packages/botocore/hooks.py", line 239, in _emit
    response = handler(**kwargs)
               ^^^^^^^^^^^^^^^^^
  File "/home/airflow/.local/lib/python3.12/site-packages/botocore/retryhandler.py", line 207, in __call__
    if self._checker(**checker_kwargs):
       ^^^^^^^^^^^^^^^^^^^^^^^^^^^^^^^
  File "/home/airflow/.local/lib/python3.12/site-packages/botocore/retryhandler.py", line 284, in __call__
    should_retry = self._should_retry(
                   ^^^^^^^^^^^^^^^^^^^
  File "/home/airflow/.local/lib/python3.12/site-packages/botocore/retryhandler.py", line 320, in _should_retry
    return self._checker(attempt_number, response, caught_exception)
           ^^^^^^^^^^^^^^^^^^^^^^^^^^^^^^^^^^^^^^^^^^^^^^^^^^^^^^^^^
  File "/home/airflow/.local/lib/python3.12/site-packages/botocore/retryhandler.py", line 363, in __call__
    checker_response = checker(
                       ^^^^^^^^
  File "/home/airflow/.local/lib/python3.12/site-packages/botocore/retryhandler.py", line 247, in __call__
    return self._check_caught_exception(
           ^^^^^^^^^^^^^^^^^^^^^^^^^^^^^
  File "/home/airflow/.local/lib/python3.12/site-packages/botocore/retryhandler.py", line 416, in _check_caught_exception
    raise caught_exception
  File "/home/airflow/.local/lib/python3.12/site-packages/botocore/endpoint.py", line 281, in _do_get_response
    http_response = self._send(request)
                    ^^^^^^^^^^^^^^^^^^^
  File "/home/airflow/.local/lib/python3.12/site-packages/botocore/endpoint.py", line 377, in _send
    return self.http_session.send(request)
           ^^^^^^^^^^^^^^^^^^^^^^^^^^^^^^^
  File "/home/airflow/.local/lib/python3.12/site-packages/botocore/httpsession.py", line 501, in send
    raise ReadTimeoutError(endpoint_url=request.url, error=e)
botocore.exceptions.ReadTimeoutError: Read timeout on endpoint URL: "https://lambda.eu-central-1.amazonaws.com/2015-03-31/functions/sentiment_ntbk/invocations"
[2025-10-21T23:01:45.428+0000] {taskinstance.py:1206} INFO - Marking task as FAILED. dag_id=game_sentiment_data_pipeline, task_id=sent_analysis, run_id=manual__2025-10-21T22:55:02.148183+00:00, execution_date=20251021T225502, start_date=20251021T225634, end_date=20251021T230145
[2025-10-21T23:01:45.445+0000] {standard_task_runner.py:110} ERROR - Failed to execute job 124 for task sent_analysis (Read timeout on endpoint URL: "https://lambda.eu-central-1.amazonaws.com/2015-03-31/functions/sentiment_ntbk/invocations"; 163)
[2025-10-21T23:01:45.461+0000] {local_task_job_runner.py:243} INFO - Task exited with return code 1
[2025-10-21T23:01:45.490+0000] {taskinstance.py:3503} INFO - 0 downstream tasks scheduled from follow-on schedule check
[2025-10-21T23:01:45.493+0000] {local_task_job_runner.py:222} INFO - ::endgroup::
